2019-09-02 15:50:08.956 [error] <0.958.0> ** Task <0.958.0> terminating
** Started from 'Elixir.Archive.Supervisor'
** When function  == fun Elixir.Archive.StartAllCamerasVisor:run/1
**      arguments == [[]]
** Reason for termination == 
** {#{'__exception__' => true,'__struct__' => 'Elixir.DBConnection.ConnectionError',message => <<"connection not available and request was dropped from queue after 2405ms. You can configure how long requests wait in the queue using :queue_target and :queue_interval. See DBConnection.start_link/2 for more information">>},[{'Elixir.Ecto.Adapters.SQL',raise_sql_call_error,1,[{file,"lib/ecto/adapters/sql.ex"},{line,618}]},{'Elixir.Ecto.Adapters.SQL',execute,5,[{file,"lib/ecto/adapters/sql.ex"},{line,551}]},{'Elixir.Ecto.Repo.Queryable',execute,4,[{file,"lib/ecto/repo/queryable.ex"},{line,153}]},{'Elixir.Ecto.Repo.Queryable',all,3,[{file,"lib/ecto/repo/queryable.ex"},{line,18}]},{'Elixir.Archive.StartAllCamerasVisor',run,1,[{file,"lib/archive/start_all_cameras_visor.ex"},{line,13}]},{'Elixir.Task.Supervised',invoke_mfa,2,[{file,"lib/task/supervised.ex"},{line,90}]},{proc_lib,init_p_do_apply,3,[{file,"proc_lib.erl"},{line,249}]}]}
2019-09-02 15:50:09.003 [error] <0.958.0> CRASH REPORT Process <0.958.0> with 0 neighbours crashed with reason: #{'__exception__' => true,'__struct__' => 'Elixir.DBConnection.ConnectionError',message => <<"connection not available and request was dropped from queue after 2405ms. You can configure how long requests wait in the queue using :queue_target and :queue_interval. See DBConnection.start_link/2 for more information">>} in 'Elixir.Ecto.Adapters.SQL':raise_sql_call_error/1 line 618
2019-09-02 15:50:09.004 [error] <0.825.0> Supervisor 'Elixir.Archive.Supervisor' had child 'Elixir.Archive.StartAllCamerasVisor' started with 'Elixir.Archive.StartAllCamerasVisor':start_link([]) at <0.958.0> exit with reason #{'__exception__' => true,'__struct__' => 'Elixir.DBConnection.ConnectionError',message => <<"connection not available and request was dropped from queue after 2405ms. You can configure how long requests wait in the queue using :queue_target and :queue_interval. See DBConnection.start_link/2 for more information">>} in 'Elixir.Ecto.Adapters.SQL':raise_sql_call_error/1 line 618 in context child_terminated
2019-09-02 15:50:11.405 [error] <0.411.0>@Elixir.Tzdata.Util:first_matching_weekday_in_month:73 gen_server tzdata_release_updater terminated with reason: no function clause matching 'Elixir.Tzdata.Util':first_matching_weekday_in_month(1932, 4, 7, []) line 73
2019-09-02 15:50:11.420 [error] <0.411.0>@Elixir.Tzdata.Util:first_matching_weekday_in_month:73 CRASH REPORT Process tzdata_release_updater with 0 neighbours crashed with reason: no function clause matching 'Elixir.Tzdata.Util':first_matching_weekday_in_month(1932, 4, 7, []) line 73
2019-09-02 15:50:11.421 [error] <0.405.0>@Elixir.Tzdata.Util:first_matching_weekday_in_month:73 Supervisor {<0.405.0>,'Elixir.Supervisor.Default'} had child 'Elixir.Tzdata.ReleaseUpdater' started with 'Elixir.Tzdata.ReleaseUpdater':start_link() at <0.411.0> exit with reason no function clause matching 'Elixir.Tzdata.Util':first_matching_weekday_in_month(1932, 4, 7, []) line 73 in context child_terminated
2019-09-05 15:14:52.872 [error] <0.980.0> ** Task <0.980.0> terminating
** Started from 'Elixir.Archive.Supervisor'
** When function  == fun Elixir.Archive.StartAllCamerasVisor:run/1
**      arguments == [[]]
** Reason for termination == 
** {#{'__exception__' => true,'__struct__' => 'Elixir.DBConnection.ConnectionError',message => <<"connection not available and request was dropped from queue after 2374ms. You can configure how long requests wait in the queue using :queue_target and :queue_interval. See DBConnection.start_link/2 for more information">>},[{'Elixir.Ecto.Adapters.SQL',raise_sql_call_error,1,[{file,"lib/ecto/adapters/sql.ex"},{line,618}]},{'Elixir.Ecto.Adapters.SQL',execute,5,[{file,"lib/ecto/adapters/sql.ex"},{line,551}]},{'Elixir.Ecto.Repo.Queryable',execute,4,[{file,"lib/ecto/repo/queryable.ex"},{line,153}]},{'Elixir.Ecto.Repo.Queryable',all,3,[{file,"lib/ecto/repo/queryable.ex"},{line,18}]},{'Elixir.Archive.StartAllCamerasVisor',run,1,[{file,"lib/archive/start_all_cameras_visor.ex"},{line,13}]},{'Elixir.Task.Supervised',invoke_mfa,2,[{file,"lib/task/supervised.ex"},{line,90}]},{proc_lib,init_p_do_apply,3,[{file,"proc_lib.erl"},{line,249}]}]}
2019-09-05 15:14:52.908 [error] <0.980.0> CRASH REPORT Process <0.980.0> with 0 neighbours crashed with reason: #{'__exception__' => true,'__struct__' => 'Elixir.DBConnection.ConnectionError',message => <<"connection not available and request was dropped from queue after 2374ms. You can configure how long requests wait in the queue using :queue_target and :queue_interval. See DBConnection.start_link/2 for more information">>} in 'Elixir.Ecto.Adapters.SQL':raise_sql_call_error/1 line 618
2019-09-05 15:14:52.909 [error] <0.847.0> Supervisor 'Elixir.Archive.Supervisor' had child 'Elixir.Archive.StartAllCamerasVisor' started with 'Elixir.Archive.StartAllCamerasVisor':start_link([]) at <0.980.0> exit with reason #{'__exception__' => true,'__struct__' => 'Elixir.DBConnection.ConnectionError',message => <<"connection not available and request was dropped from queue after 2374ms. You can configure how long requests wait in the queue using :queue_target and :queue_interval. See DBConnection.start_link/2 for more information">>} in 'Elixir.Ecto.Adapters.SQL':raise_sql_call_error/1 line 618 in context child_terminated
2019-09-06 11:09:22.709 [error] <0.927.0> ** Task <0.927.0> terminating
** Started from 'Elixir.Archive.Supervisor'
** When function  == fun Elixir.Archive.StartAllCamerasVisor:run/1
**      arguments == [[]]
** Reason for termination == 
** {#{'__exception__' => true,'__struct__' => 'Elixir.DBConnection.ConnectionError',message => <<"connection not available and request was dropped from queue after 2415ms. You can configure how long requests wait in the queue using :queue_target and :queue_interval. See DBConnection.start_link/2 for more information">>},[{'Elixir.Ecto.Adapters.SQL',raise_sql_call_error,1,[{file,"lib/ecto/adapters/sql.ex"},{line,618}]},{'Elixir.Ecto.Adapters.SQL',execute,5,[{file,"lib/ecto/adapters/sql.ex"},{line,551}]},{'Elixir.Ecto.Repo.Queryable',execute,4,[{file,"lib/ecto/repo/queryable.ex"},{line,153}]},{'Elixir.Ecto.Repo.Queryable',all,3,[{file,"lib/ecto/repo/queryable.ex"},{line,18}]},{'Elixir.Archive.StartAllCamerasVisor',run,1,[{file,"lib/archive/start_all_cameras_visor.ex"},{line,13}]},{'Elixir.Task.Supervised',invoke_mfa,2,[{file,"lib/task/supervised.ex"},{line,90}]},{proc_lib,init_p_do_apply,3,[{file,"proc_lib.erl"},{line,249}]}]}
2019-09-06 11:09:22.798 [error] <0.927.0> CRASH REPORT Process <0.927.0> with 0 neighbours crashed with reason: #{'__exception__' => true,'__struct__' => 'Elixir.DBConnection.ConnectionError',message => <<"connection not available and request was dropped from queue after 2415ms. You can configure how long requests wait in the queue using :queue_target and :queue_interval. See DBConnection.start_link/2 for more information">>} in 'Elixir.Ecto.Adapters.SQL':raise_sql_call_error/1 line 618
2019-09-06 11:09:22.800 [error] <0.794.0> Supervisor 'Elixir.Archive.Supervisor' had child 'Elixir.Archive.StartAllCamerasVisor' started with 'Elixir.Archive.StartAllCamerasVisor':start_link([]) at <0.927.0> exit with reason #{'__exception__' => true,'__struct__' => 'Elixir.DBConnection.ConnectionError',message => <<"connection not available and request was dropped from queue after 2415ms. You can configure how long requests wait in the queue using :queue_target and :queue_interval. See DBConnection.start_link/2 for more information">>} in 'Elixir.Ecto.Adapters.SQL':raise_sql_call_error/1 line 618 in context child_terminated
2019-09-06 11:09:25.309 [error] <0.380.0>@Elixir.Tzdata.Util:first_matching_weekday_in_month:73 gen_server tzdata_release_updater terminated with reason: no function clause matching 'Elixir.Tzdata.Util':first_matching_weekday_in_month(1932, 4, 7, []) line 73
2019-09-06 11:09:25.317 [error] <0.380.0>@Elixir.Tzdata.Util:first_matching_weekday_in_month:73 CRASH REPORT Process tzdata_release_updater with 0 neighbours crashed with reason: no function clause matching 'Elixir.Tzdata.Util':first_matching_weekday_in_month(1932, 4, 7, []) line 73
2019-09-06 11:09:25.318 [error] <0.374.0>@Elixir.Tzdata.Util:first_matching_weekday_in_month:73 Supervisor {<0.374.0>,'Elixir.Supervisor.Default'} had child 'Elixir.Tzdata.ReleaseUpdater' started with 'Elixir.Tzdata.ReleaseUpdater':start_link() at <0.380.0> exit with reason no function clause matching 'Elixir.Tzdata.Util':first_matching_weekday_in_month(1932, 4, 7, []) line 73 in context child_terminated
2019-10-16 18:17:59.206 [error] <0.1008.0>@Elixir.Archive.VideoVisor:create_dir:59 CRASH REPORT Process <0.1008.0> with 0 neighbours crashed with reason: bad argument in 'Elixir.Archive.VideoVisor':create_dir/2 line 59
2019-10-16 18:17:59.206 [error] <0.1009.0>@Elixir.Archive.VideoVisor:create_dir:59 CRASH REPORT Process <0.1009.0> with 0 neighbours crashed with reason: bad argument in 'Elixir.Archive.VideoVisor':create_dir/2 line 59
2019-10-16 18:18:11.013 [error] <0.1153.0> CRASH REPORT Process <0.1153.0> with 0 neighbours exited with reason: {{#{'__exception__' => true,'__struct__' => 'Elixir.Phoenix.Router.NoRouteError',conn => #{'__struct__' => 'Elixir.Plug.Conn',adapter => {'Elixir.Plug.Cowboy.Conn',#{bindings => #{},body_length => 0,cert => undefined,has_body => false,headers => #{<<"accept">> => <<"text/html,application/xhtml+xml,application/xml;q=0.9,image/webp,image/apng,*/*;q=0.8,application/signed-exchange;v=b3">>,<<"accept-encoding">> => <<"gzip, deflate, br">>,<<"accept-language">> => <<"ru-RU,ru;q=0.9,en-US;q=0.8...">>,...},...}},...},...},...},...} in 'Elixir.Phoenix.Endpoint.Cowboy2Handler':init/2 line 42 in 'Elixir.Phoenix.Endpoint.Cowboy2Handler':init/2 line 42
2019-10-16 18:18:11.179 [error] <0.671.0> Lager event handler error_logger_lager_h exited with reason {'EXIT',{{case_clause,['Elixir.DomoapiWeb.Endpoint.HTTP',<0.1151.0>,1,<0.1153.0>,{{#{'__exception__' => true,'__struct__' => 'Elixir.Phoenix.Router.NoRouteError',conn => #{'__struct__' => 'Elixir.Plug.Conn',adapter => {'Elixir.Plug.Cowboy.Conn',#{bindings => #{},body_length => 0,cert => undefined,has_body => false,headers => #{<<"accept">> => <<"text/html,application/xhtml+xml,application/xml;q=0.9,image/webp,image/apng,*/*;q=0.8,application/signed-exchange;v=b3">>,<<"accept-encodin...">> => ...,...},...}},...},...},...},...},...]},...}}
2019-10-16 18:18:11.488 [error] <0.1156.0> CRASH REPORT Process <0.1156.0> with 0 neighbours exited with reason: {{#{'__exception__' => true,'__struct__' => 'Elixir.Phoenix.Router.NoRouteError',conn => #{'__struct__' => 'Elixir.Plug.Conn',adapter => {'Elixir.Plug.Cowboy.Conn',#{bindings => #{},body_length => 0,cert => undefined,has_body => false,headers => #{<<"accept">> => <<"*/*">>,<<"accept-encoding">> => <<"gzip, deflate, br">>,<<"accept-language">> => <<"ru-RU,ru;q=0.9,en-US;q=0.8,en;q=0.7">>,<<"connection">> => <<"keep-alive">>,<<"host">> => <<"localhost:4000">>,<<"origin">> => <<"http://loca...">>,...},...}},...},...},...},...} in 'Elixir.Phoenix.Endpoint.Cowboy2Handler':init/2 line 42 in 'Elixir.Phoenix.Endpoint.Cowboy2Handler':init/2 line 42
2019-10-16 18:18:11.497 [error] <0.671.0> Lager event handler error_logger_lager_h exited with reason {'EXIT',{{case_clause,['Elixir.DomoapiWeb.Endpoint.HTTP',<0.1151.0>,2,<0.1156.0>,{{#{'__exception__' => true,'__struct__' => 'Elixir.Phoenix.Router.NoRouteError',conn => #{'__struct__' => 'Elixir.Plug.Conn',adapter => {'Elixir.Plug.Cowboy.Conn',#{bindings => #{},body_length => 0,cert => undefined,has_body => false,headers => #{<<"accept">> => <<"*/*">>,<<"accept-encoding">> => <<"gzip, deflate, br">>,<<"accept-language">> => <<"ru-RU,ru;q=0.9,en-US;q=0.8,en;q=0.7">>,<<"connection">> => <<"...">>,...},...}},...},...},...},...},...]},...}}
2019-10-16 18:18:11.666 [error] <0.1159.0> CRASH REPORT Process <0.1159.0> with 0 neighbours exited with reason: {{#{'__exception__' => true,'__struct__' => 'Elixir.Phoenix.Router.NoRouteError',conn => #{'__struct__' => 'Elixir.Plug.Conn',adapter => {'Elixir.Plug.Cowboy.Conn',#{bindings => #{},body_length => 0,cert => undefined,has_body => false,headers => #{<<"accept">> => <<"image/webp,image/apng,image/*,*/*;q=0.8">>,<<"accept-encoding">> => <<"gzip, deflate, br">>,<<"accept-language">> => <<"ru-RU,ru;q=0.9,en-US;q=0.8,en;q=0.7">>,<<"connection">> => <<"keep-alive">>,<<"host">> => <<"localhost:40...">>,...},...}},...},...},...},...} in 'Elixir.Phoenix.Endpoint.Cowboy2Handler':init/2 line 42 in 'Elixir.Phoenix.Endpoint.Cowboy2Handler':init/2 line 42
2019-10-16 18:18:11.678 [error] <0.671.0> Lager event handler error_logger_lager_h exited with reason {'EXIT',{{case_clause,['Elixir.DomoapiWeb.Endpoint.HTTP',<0.1151.0>,3,<0.1159.0>,{{#{'__exception__' => true,'__struct__' => 'Elixir.Phoenix.Router.NoRouteError',conn => #{'__struct__' => 'Elixir.Plug.Conn',adapter => {'Elixir.Plug.Cowboy.Conn',#{bindings => #{},body_length => 0,cert => undefined,has_body => false,headers => #{<<"accept">> => <<"image/webp,image/apng,image/*,*/*;q=0.8">>,<<"accept-encoding">> => <<"gzip, deflate, br">>,<<"accept-language">> => <<"ru-RU,ru;q=0.9,en-US;q=...">>,...},...}},...},...},...},...},...]},...}}
2019-11-18 15:11:02.007 [error] <0.1176.0>@Elixir.Archive.VideoVisor:create_dir:59 CRASH REPORT Process <0.1176.0> with 0 neighbours crashed with reason: bad argument in 'Elixir.Archive.VideoVisor':create_dir/2 line 59
2019-11-18 15:30:25.013 [error] <0.1176.0>@Elixir.Archive.VideoVisor:create_dir:59 CRASH REPORT Process <0.1176.0> with 0 neighbours crashed with reason: bad argument in 'Elixir.Archive.VideoVisor':create_dir/2 line 59
2019-11-18 16:24:57.686 [error] <0.1343.0> CRASH REPORT Process <0.1343.0> with 0 neighbours exited with reason: {{#{'__exception__' => true,'__struct__' => 'Elixir.FunctionClauseError',args => nil,arity => 2,clauses => nil,function => call,kind => nil,module => 'Elixir.DomoapiUserWeb.FallbackController'},[{'Elixir.DomoapiUserWeb.FallbackController',call,[#{'__struct__' => 'Elixir.Plug.Conn',adapter => {'Elixir.Plug.Cowboy.Conn',#{bindings => #{},body_length => 199,cert => undefined,has_body => true,has_read_body => true,headers => #{<<"accept-charset">> => <<"UTF-8">>,<<"accept-encoding">> => <<"g...">>,...},...}},...},...],...},...]},...} in 'Elixir.Phoenix.Endpoint.Cowboy2Handler':init/2 line 42 in 'Elixir.Phoenix.Endpoint.Cowboy2Handler':init/2 line 42
2019-11-18 16:24:57.726 [error] <0.455.0> Lager event handler error_logger_lager_h exited with reason {'EXIT',{{case_clause,['Elixir.DomoapiUserWeb.Endpoint.HTTP',<0.1342.0>,1,<0.1343.0>,{{#{'__exception__' => true,'__struct__' => 'Elixir.FunctionClauseError',args => nil,arity => 2,clauses => nil,function => call,kind => nil,module => 'Elixir.DomoapiUserWeb.FallbackController'},[{'Elixir.DomoapiUserWeb.FallbackController',call,[#{'__struct__' => 'Elixir.Plug.Conn',adapter => {'Elixir.Plug.Cowboy.Conn',#{bindings => #{},body_length => 199,cert => undefined,has_body => true,has_read_body => true,...}},...},...],...},...]},...},...]},...}}
2019-11-18 16:24:57.778 [error] <0.1348.0> CRASH REPORT Process <0.1348.0> with 0 neighbours exited with reason: {{#{'__exception__' => true,'__struct__' => 'Elixir.FunctionClauseError',args => nil,arity => 2,clauses => nil,function => call,kind => nil,module => 'Elixir.DomoapiUserWeb.FallbackController'},[{'Elixir.DomoapiUserWeb.FallbackController',call,[#{'__struct__' => 'Elixir.Plug.Conn',adapter => {'Elixir.Plug.Cowboy.Conn',#{bindings => #{},body_length => 231,cert => undefined,has_body => true,has_read_body => true,headers => #{<<"accept-charset">> => <<"UTF-8">>,<<"accept-encoding">> => <<"g...">>,...},...}},...},...],...},...]},...} in 'Elixir.Phoenix.Endpoint.Cowboy2Handler':init/2 line 42 in 'Elixir.Phoenix.Endpoint.Cowboy2Handler':init/2 line 42
2019-11-18 16:24:57.789 [error] <0.455.0> Lager event handler error_logger_lager_h exited with reason {'EXIT',{{case_clause,['Elixir.DomoapiUserWeb.Endpoint.HTTP',<0.1347.0>,1,<0.1348.0>,{{#{'__exception__' => true,'__struct__' => 'Elixir.FunctionClauseError',args => nil,arity => 2,clauses => nil,function => call,kind => nil,module => 'Elixir.DomoapiUserWeb.FallbackController'},[{'Elixir.DomoapiUserWeb.FallbackController',call,[#{'__struct__' => 'Elixir.Plug.Conn',adapter => {'Elixir.Plug.Cowboy.Conn',#{bindings => #{},body_length => 231,cert => undefined,has_body => true,has_read_body => true,...}},...},...],...},...]},...},...]},...}}
2019-11-18 16:24:57.828 [error] <0.1353.0> CRASH REPORT Process <0.1353.0> with 0 neighbours exited with reason: {{#{'__exception__' => true,'__struct__' => 'Elixir.FunctionClauseError',args => nil,arity => 2,clauses => nil,function => call,kind => nil,module => 'Elixir.DomoapiUserWeb.FallbackController'},[{'Elixir.DomoapiUserWeb.FallbackController',call,[#{'__struct__' => 'Elixir.Plug.Conn',adapter => {'Elixir.Plug.Cowboy.Conn',#{bindings => #{},body_length => 230,cert => undefined,has_body => true,has_read_body => true,headers => #{<<"accept-charset">> => <<"UTF-8">>,<<"accept-encoding">> => <<"g...">>,...},...}},...},...],...},...]},...} in 'Elixir.Phoenix.Endpoint.Cowboy2Handler':init/2 line 42 in 'Elixir.Phoenix.Endpoint.Cowboy2Handler':init/2 line 42
2019-11-18 16:24:57.839 [error] <0.455.0> Lager event handler error_logger_lager_h exited with reason {'EXIT',{{case_clause,['Elixir.DomoapiUserWeb.Endpoint.HTTP',<0.1352.0>,1,<0.1353.0>,{{#{'__exception__' => true,'__struct__' => 'Elixir.FunctionClauseError',args => nil,arity => 2,clauses => nil,function => call,kind => nil,module => 'Elixir.DomoapiUserWeb.FallbackController'},[{'Elixir.DomoapiUserWeb.FallbackController',call,[#{'__struct__' => 'Elixir.Plug.Conn',adapter => {'Elixir.Plug.Cowboy.Conn',#{bindings => #{},body_length => 230,cert => undefined,has_body => true,has_read_body => true,...}},...},...],...},...]},...},...]},...}}
2019-11-18 16:24:57.888 [error] <0.1351.0> CRASH REPORT Process <0.1351.0> with 0 neighbours exited with reason: {{#{'__exception__' => true,'__struct__' => 'Elixir.FunctionClauseError',args => nil,arity => 2,clauses => nil,function => call,kind => nil,module => 'Elixir.DomoapiUserWeb.FallbackController'},[{'Elixir.DomoapiUserWeb.FallbackController',call,[#{'__struct__' => 'Elixir.Plug.Conn',adapter => {'Elixir.Plug.Cowboy.Conn',#{bindings => #{},body_length => 14,cert => undefined,has_body => true,has_read_body => true,headers => #{<<"accept-charset">> => <<"UTF-8">>,<<"accept-encoding">> => <<"gz...">>,...},...}},...},...],...},...]},...} in 'Elixir.Phoenix.Endpoint.Cowboy2Handler':init/2 line 42 in 'Elixir.Phoenix.Endpoint.Cowboy2Handler':init/2 line 42
2019-11-18 16:24:57.899 [error] <0.455.0> Lager event handler error_logger_lager_h exited with reason {'EXIT',{{case_clause,['Elixir.DomoapiUserWeb.Endpoint.HTTP',<0.1350.0>,1,<0.1351.0>,{{#{'__exception__' => true,'__struct__' => 'Elixir.FunctionClauseError',args => nil,arity => 2,clauses => nil,function => call,kind => nil,module => 'Elixir.DomoapiUserWeb.FallbackController'},[{'Elixir.DomoapiUserWeb.FallbackController',call,[#{'__struct__' => 'Elixir.Plug.Conn',adapter => {'Elixir.Plug.Cowboy.Conn',#{bindings => #{},body_length => 14,cert => undefined,has_body => true,has_read_body => true,...}},...},...],...},...]},...},...]},...}}
2019-11-18 16:26:46.271 [error] <0.1397.0> CRASH REPORT Process <0.1397.0> with 0 neighbours exited with reason: {{#{'__exception__' => true,'__struct__' => 'Elixir.FunctionClauseError',args => nil,arity => 2,clauses => nil,function => call,kind => nil,module => 'Elixir.DomoapiUserWeb.FallbackController'},[{'Elixir.DomoapiUserWeb.FallbackController',call,[#{'__struct__' => 'Elixir.Plug.Conn',adapter => {'Elixir.Plug.Cowboy.Conn',#{bindings => #{},body_length => 199,cert => undefined,has_body => true,has_read_body => true,headers => #{<<"accept-charset">> => <<"UTF-8">>,<<"accept-encoding">> => <<"g...">>,...},...}},...},...],...},...]},...} in 'Elixir.Phoenix.Endpoint.Cowboy2Handler':init/2 line 42 in 'Elixir.Phoenix.Endpoint.Cowboy2Handler':init/2 line 42
2019-11-18 16:26:46.283 [error] <0.455.0> Lager event handler error_logger_lager_h exited with reason {'EXIT',{{case_clause,['Elixir.DomoapiUserWeb.Endpoint.HTTP',<0.1396.0>,1,<0.1397.0>,{{#{'__exception__' => true,'__struct__' => 'Elixir.FunctionClauseError',args => nil,arity => 2,clauses => nil,function => call,kind => nil,module => 'Elixir.DomoapiUserWeb.FallbackController'},[{'Elixir.DomoapiUserWeb.FallbackController',call,[#{'__struct__' => 'Elixir.Plug.Conn',adapter => {'Elixir.Plug.Cowboy.Conn',#{bindings => #{},body_length => 199,cert => undefined,has_body => true,has_read_body => true,...}},...},...],...},...]},...},...]},...}}
2019-11-18 16:26:46.357 [error] <0.1401.0> CRASH REPORT Process <0.1401.0> with 0 neighbours exited with reason: {{#{'__exception__' => true,'__struct__' => 'Elixir.FunctionClauseError',args => nil,arity => 2,clauses => nil,function => call,kind => nil,module => 'Elixir.DomoapiUserWeb.FallbackController'},[{'Elixir.DomoapiUserWeb.FallbackController',call,[#{'__struct__' => 'Elixir.Plug.Conn',adapter => {'Elixir.Plug.Cowboy.Conn',#{bindings => #{},body_length => 231,cert => undefined,has_body => true,has_read_body => true,headers => #{<<"accept-charset">> => <<"UTF-8">>,<<"accept-encoding">> => <<"g...">>,...},...}},...},...],...},...]},...} in 'Elixir.Phoenix.Endpoint.Cowboy2Handler':init/2 line 42 in 'Elixir.Phoenix.Endpoint.Cowboy2Handler':init/2 line 42
2019-11-18 16:26:46.371 [error] <0.455.0> Lager event handler error_logger_lager_h exited with reason {'EXIT',{{case_clause,['Elixir.DomoapiUserWeb.Endpoint.HTTP',<0.1400.0>,1,<0.1401.0>,{{#{'__exception__' => true,'__struct__' => 'Elixir.FunctionClauseError',args => nil,arity => 2,clauses => nil,function => call,kind => nil,module => 'Elixir.DomoapiUserWeb.FallbackController'},[{'Elixir.DomoapiUserWeb.FallbackController',call,[#{'__struct__' => 'Elixir.Plug.Conn',adapter => {'Elixir.Plug.Cowboy.Conn',#{bindings => #{},body_length => 231,cert => undefined,has_body => true,has_read_body => true,...}},...},...],...},...]},...},...]},...}}
2019-11-18 16:26:46.405 [error] <0.1405.0> CRASH REPORT Process <0.1405.0> with 0 neighbours exited with reason: {{#{'__exception__' => true,'__struct__' => 'Elixir.FunctionClauseError',args => nil,arity => 2,clauses => nil,function => call,kind => nil,module => 'Elixir.DomoapiUserWeb.FallbackController'},[{'Elixir.DomoapiUserWeb.FallbackController',call,[#{'__struct__' => 'Elixir.Plug.Conn',adapter => {'Elixir.Plug.Cowboy.Conn',#{bindings => #{},body_length => 14,cert => undefined,has_body => true,has_read_body => true,headers => #{<<"accept-charset">> => <<"UTF-8">>,<<"accept-encoding">> => <<"gz...">>,...},...}},...},...],...},...]},...} in 'Elixir.Phoenix.Endpoint.Cowboy2Handler':init/2 line 42 in 'Elixir.Phoenix.Endpoint.Cowboy2Handler':init/2 line 42
2019-11-18 16:26:46.414 [error] <0.455.0> Lager event handler error_logger_lager_h exited with reason {'EXIT',{{case_clause,['Elixir.DomoapiUserWeb.Endpoint.HTTP',<0.1404.0>,1,<0.1405.0>,{{#{'__exception__' => true,'__struct__' => 'Elixir.FunctionClauseError',args => nil,arity => 2,clauses => nil,function => call,kind => nil,module => 'Elixir.DomoapiUserWeb.FallbackController'},[{'Elixir.DomoapiUserWeb.FallbackController',call,[#{'__struct__' => 'Elixir.Plug.Conn',adapter => {'Elixir.Plug.Cowboy.Conn',#{bindings => #{},body_length => 14,cert => undefined,has_body => true,has_read_body => true,...}},...},...],...},...]},...},...]},...}}
2019-11-18 16:26:46.469 [error] <0.1409.0> CRASH REPORT Process <0.1409.0> with 0 neighbours exited with reason: {{#{'__exception__' => true,'__struct__' => 'Elixir.FunctionClauseError',args => nil,arity => 2,clauses => nil,function => call,kind => nil,module => 'Elixir.DomoapiUserWeb.FallbackController'},[{'Elixir.DomoapiUserWeb.FallbackController',call,[#{'__struct__' => 'Elixir.Plug.Conn',adapter => {'Elixir.Plug.Cowboy.Conn',#{bindings => #{},body_length => 230,cert => undefined,has_body => true,has_read_body => true,headers => #{<<"accept-charset">> => <<"UTF-8">>,<<"accept-encoding">> => <<"g...">>,...},...}},...},...],...},...]},...} in 'Elixir.Phoenix.Endpoint.Cowboy2Handler':init/2 line 42 in 'Elixir.Phoenix.Endpoint.Cowboy2Handler':init/2 line 42
2019-11-18 16:26:46.479 [error] <0.455.0> Lager event handler error_logger_lager_h exited with reason {'EXIT',{{case_clause,['Elixir.DomoapiUserWeb.Endpoint.HTTP',<0.1408.0>,1,<0.1409.0>,{{#{'__exception__' => true,'__struct__' => 'Elixir.FunctionClauseError',args => nil,arity => 2,clauses => nil,function => call,kind => nil,module => 'Elixir.DomoapiUserWeb.FallbackController'},[{'Elixir.DomoapiUserWeb.FallbackController',call,[#{'__struct__' => 'Elixir.Plug.Conn',adapter => {'Elixir.Plug.Cowboy.Conn',#{bindings => #{},body_length => 230,cert => undefined,has_body => true,has_read_body => true,...}},...},...],...},...]},...},...]},...}}
2019-11-18 16:35:39.059 [error] <0.1424.0> CRASH REPORT Process <0.1424.0> with 0 neighbours exited with reason: {{#{'__exception__' => true,'__struct__' => 'Elixir.Phoenix.Router.NoRouteError',conn => #{'__struct__' => 'Elixir.Plug.Conn',adapter => {'Elixir.Plug.Cowboy.Conn',#{bindings => #{},body_length => 0,cert => undefined,has_body => false,headers => #{<<"accept">> => <<"text/html,application/xhtml+xml,application/xml;q=0.9,image/webp,image/apng,*/*;q=0.8,application/signed-exchange;v=b3">>,<<"accept-encoding">> => <<"gzip, deflate, br">>,<<"accept-language">> => <<"ru-RU,ru;q=0.9,en-US;q=0.8...">>,...},...}},...},...},...},...} in 'Elixir.Phoenix.Endpoint.Cowboy2Handler':init/2 line 42 in 'Elixir.Phoenix.Endpoint.Cowboy2Handler':init/2 line 42
2019-11-18 16:35:39.096 [error] <0.455.0> Lager event handler error_logger_lager_h exited with reason {'EXIT',{{case_clause,['Elixir.DomoapiUserWeb.Endpoint.HTTP',<0.1423.0>,1,<0.1424.0>,{{#{'__exception__' => true,'__struct__' => 'Elixir.Phoenix.Router.NoRouteError',conn => #{'__struct__' => 'Elixir.Plug.Conn',adapter => {'Elixir.Plug.Cowboy.Conn',#{bindings => #{},body_length => 0,cert => undefined,has_body => false,headers => #{<<"accept">> => <<"text/html,application/xhtml+xml,application/xml;q=0.9,image/webp,image/apng,*/*;q=0.8,application/signed-exchange;v=b3">>,<<"accept-enc...">> => ...,...},...}},...},...},...},...},...]},...}}
2019-11-18 16:36:32.338 [error] <0.1460.0> CRASH REPORT Process <0.1460.0> with 0 neighbours exited with reason: {{#{'__exception__' => true,'__struct__' => 'Elixir.Phoenix.Router.NoRouteError',conn => #{'__struct__' => 'Elixir.Plug.Conn',adapter => {'Elixir.Plug.Cowboy.Conn',#{bindings => #{},body_length => 0,cert => undefined,has_body => false,headers => #{<<"accept">> => <<"text/html,application/xhtml+xml,application/xml;q=0.9,image/webp,image/apng,*/*;q=0.8,application/signed-exchange;v=b3">>,<<"accept-encoding">> => <<"gzip, deflate, br">>,<<"accept-language">> => <<"ru-RU,ru;q=0.9,en-US;q=0.8...">>,...},...}},...},...},...},...} in 'Elixir.Phoenix.Endpoint.Cowboy2Handler':init/2 line 42 in 'Elixir.Phoenix.Endpoint.Cowboy2Handler':init/2 line 42
2019-11-18 16:36:32.344 [error] <0.455.0> Lager event handler error_logger_lager_h exited with reason {'EXIT',{{case_clause,['Elixir.DomoapiUserWeb.Endpoint.HTTP',<0.1459.0>,1,<0.1460.0>,{{#{'__exception__' => true,'__struct__' => 'Elixir.Phoenix.Router.NoRouteError',conn => #{'__struct__' => 'Elixir.Plug.Conn',adapter => {'Elixir.Plug.Cowboy.Conn',#{bindings => #{},body_length => 0,cert => undefined,has_body => false,headers => #{<<"accept">> => <<"text/html,application/xhtml+xml,application/xml;q=0.9,image/webp,image/apng,*/*;q=0.8,application/signed-exchange;v=b3">>,<<"accept-enc...">> => ...,...},...}},...},...},...},...},...]},...}}
2019-11-18 16:36:38.835 [error] <0.1467.0> CRASH REPORT Process <0.1467.0> with 0 neighbours exited with reason: {{#{'__exception__' => true,'__struct__' => 'Elixir.Phoenix.Router.NoRouteError',conn => #{'__struct__' => 'Elixir.Plug.Conn',adapter => {'Elixir.Plug.Cowboy.Conn',#{bindings => #{},body_length => 0,cert => undefined,has_body => false,headers => #{<<"accept">> => <<"text/html,application/xhtml+xml,application/xml;q=0.9,image/webp,image/apng,*/*;q=0.8,application/signed-exchange;v=b3">>,<<"accept-encoding">> => <<"gzip, deflate, br">>,<<"accept-language">> => <<"ru-RU,ru;q=0.9,en-US;q=0.8...">>,...},...}},...},...},...},...} in 'Elixir.Phoenix.Endpoint.Cowboy2Handler':init/2 line 42 in 'Elixir.Phoenix.Endpoint.Cowboy2Handler':init/2 line 42
2019-11-18 16:36:38.841 [error] <0.455.0> Lager event handler error_logger_lager_h exited with reason {'EXIT',{{case_clause,['Elixir.DomoapiWeb.Endpoint.HTTP',<0.1466.0>,1,<0.1467.0>,{{#{'__exception__' => true,'__struct__' => 'Elixir.Phoenix.Router.NoRouteError',conn => #{'__struct__' => 'Elixir.Plug.Conn',adapter => {'Elixir.Plug.Cowboy.Conn',#{bindings => #{},body_length => 0,cert => undefined,has_body => false,headers => #{<<"accept">> => <<"text/html,application/xhtml+xml,application/xml;q=0.9,image/webp,image/apng,*/*;q=0.8,application/signed-exchange;v=b3">>,<<"accept-encodin...">> => ...,...},...}},...},...},...},...},...]},...}}
2019-11-18 18:16:59.511 [error] <0.1891.0> CRASH REPORT Process <0.1891.0> with 0 neighbours exited with reason: {{#{'__exception__' => true,'__struct__' => 'Elixir.Phoenix.Router.NoRouteError',conn => #{'__struct__' => 'Elixir.Plug.Conn',adapter => {'Elixir.Plug.Cowboy.Conn',#{bindings => #{},body_length => 0,cert => undefined,has_body => false,headers => #{<<"accept-encoding">> => <<"gzip">>,<<"connection">> => <<"upgrade">>,<<"host">> => <<"3.123.78.125">>,<<"user-agent">> => <<"Mozilla/5.0 (Windows NT 10.0; Win64; x64) AppleWebKit/537.36 (KHTML, like Gecko) Chrome/74.0.3729.169 Safari/537.36">>,...},...}},...},...},...},...} in 'Elixir.Phoenix.Endpoint.Cowboy2Handler':init/2 line 42 in 'Elixir.Phoenix.Endpoint.Cowboy2Handler':init/2 line 42
2019-11-18 21:38:30.576 [error] <0.5087.0> CRASH REPORT Process <0.5087.0> with 0 neighbours exited with reason: {{#{'__exception__' => true,'__struct__' => 'Elixir.Phoenix.Router.NoRouteError',conn => #{'__struct__' => 'Elixir.Plug.Conn',adapter => {'Elixir.Plug.Cowboy.Conn',#{bindings => #{},body_length => 0,cert => undefined,has_body => false,headers => #{<<"accept">> => <<"*/*">>,<<"accept-encoding">> => <<"gzip">>,<<"connection">> => <<"upgrade">>,<<"host">> => <<"3.123.78.125">>,<<"user-agent">> => <<"kubectl/v1.12.0 (linux/amd64) kubernetes/0ed3388">>,<<"x-forwarded-for">> => <<"169.197.108....">>,...},...}},...},...},...},...} in 'Elixir.Phoenix.Endpoint.Cowboy2Handler':init/2 line 42 in 'Elixir.Phoenix.Endpoint.Cowboy2Handler':init/2 line 42
2019-11-18 21:38:30.615 [error] <0.447.0> Lager event handler error_logger_lager_h exited with reason {'EXIT',{{case_clause,['Elixir.DomoapiWeb.Endpoint.HTTP',<0.5086.0>,1,<0.5087.0>,{{#{'__exception__' => true,'__struct__' => 'Elixir.Phoenix.Router.NoRouteError',conn => #{'__struct__' => 'Elixir.Plug.Conn',adapter => {'Elixir.Plug.Cowboy.Conn',#{bindings => #{},body_length => 0,cert => undefined,has_body => false,headers => #{<<"accept">> => <<"*/*">>,<<"accept-encoding">> => <<"gzip">>,<<"connection">> => <<"upgrade">>,<<"host">> => <<"3.123.78.125">>,<<"user-agent">> => <<"kubectl/v1...">>,...},...}},...},...},...},...},...]},...}}
2019-11-18 22:44:55.096 [error] <0.1186.0>@Elixir.Archive.VideoVisor:create_dir:59 CRASH REPORT Process <0.1186.0> with 0 neighbours crashed with reason: bad argument in 'Elixir.Archive.VideoVisor':create_dir/2 line 59
2019-11-18 22:48:21.086 [error] <0.1207.0>@Elixir.Archive.VideoVisor:create_dir:59 CRASH REPORT Process <0.1207.0> with 0 neighbours crashed with reason: bad argument in 'Elixir.Archive.VideoVisor':create_dir/2 line 59
2019-11-18 23:03:56.065 [error] <0.1661.0> CRASH REPORT Process <0.1661.0> with 0 neighbours exited with reason: {{#{'__exception__' => true,'__struct__' => 'Elixir.BadFunctionError',term => #{'__exception__' => true,'__struct__' => 'Elixir.Phoenix.ActionClauseError',args => [#{'__struct__' => 'Elixir.Plug.Conn',adapter => {'Elixir.Plug.Cowboy.Conn',#{bindings => #{},body_length => 15,cert => undefined,has_body => true,has_read_body => true,headers => #{<<"accept-charset">> => <<"UTF-8">>,<<"accept-encoding">> => <<"gzip">>,<<"connection">> => <<"upgrade">>,<<"content-length">> => <<"15">>,<<"...">> => ...,...},...}},...},...],...}},...},...} in 'Elixir.Phoenix.Endpoint.Cowboy2Handler':init/2 line 42 in 'Elixir.Phoenix.Endpoint.Cowboy2Handler':init/2 line 42
2019-11-18 23:03:56.092 [error] <0.475.0> Lager event handler error_logger_lager_h exited with reason {'EXIT',{{case_clause,['Elixir.SignallingWeb.Endpoint.HTTP',<0.1660.0>,1,<0.1661.0>,{{#{'__exception__' => true,'__struct__' => 'Elixir.BadFunctionError',term => #{'__exception__' => true,'__struct__' => 'Elixir.Phoenix.ActionClauseError',args => [#{'__struct__' => 'Elixir.Plug.Conn',adapter => {'Elixir.Plug.Cowboy.Conn',#{bindings => #{},body_length => 15,cert => undefined,has_body => true,has_read_body => true,headers => #{<<"accept-charset">> => <<"UTF-8">>,<<"accept-encoding">> => <<...>>,...},...}},...},...],...}},...},...},...]},...}}
2019-11-18 23:15:05.339 [error] <0.1837.0> CRASH REPORT Process <0.1837.0> with 0 neighbours exited with reason: {{#{'__exception__' => true,'__struct__' => 'Elixir.FunctionClauseError',args => nil,arity => 2,clauses => nil,function => sdp_call,kind => nil,module => 'Elixir.Signalling.Notifier'},[{'Elixir.Signalling.Notifier',sdp_call,[[#{'__meta__' => #{'__struct__' => 'Elixir.Ecto.Schema.Metadata',context => nil,prefix => nil,schema => 'Elixir.Domoapi.People.Tenant',source => <<"tenants">>,state => loaded},'__struct__' => 'Elixir.Domoapi.People.Tenant',apartment => #{'__cardinality__' => one,'__field__' => ...,...},...},...],...],...},...]},...} in 'Elixir.Phoenix.Endpoint.Cowboy2Handler':init/2 line 42 in 'Elixir.Phoenix.Endpoint.Cowboy2Handler':init/2 line 42
2019-11-18 23:15:05.348 [error] <0.475.0> Lager event handler error_logger_lager_h exited with reason {'EXIT',{{case_clause,['Elixir.SignallingWeb.Endpoint.HTTP',<0.1836.0>,1,<0.1837.0>,{{#{'__exception__' => true,'__struct__' => 'Elixir.FunctionClauseError',args => nil,arity => 2,clauses => nil,function => sdp_call,kind => nil,module => 'Elixir.Signalling.Notifier'},[{'Elixir.Signalling.Notifier',sdp_call,[[#{'__meta__' => #{'__struct__' => 'Elixir.Ecto.Schema.Metadata',context => nil,prefix => nil,schema => 'Elixir.Domoapi.People.Tenant',source => <<"tenants">>,state => loaded},'__struct__' => ...,...},...],...],...},...]},...},...]},...}}
2019-11-18 23:15:05.901 [error] <0.1841.0> CRASH REPORT Process <0.1841.0> with 0 neighbours exited with reason: {{#{'__exception__' => true,'__struct__' => 'Elixir.FunctionClauseError',args => nil,arity => 2,clauses => nil,function => sdp_call,kind => nil,module => 'Elixir.Signalling.Notifier'},[{'Elixir.Signalling.Notifier',sdp_call,[[#{'__meta__' => #{'__struct__' => 'Elixir.Ecto.Schema.Metadata',context => nil,prefix => nil,schema => 'Elixir.Domoapi.People.Tenant',source => <<"tenants">>,state => loaded},'__struct__' => 'Elixir.Domoapi.People.Tenant',apartment => #{'__cardinality__' => one,'__field__' => ...,...},...},...],...],...},...]},...} in 'Elixir.Phoenix.Endpoint.Cowboy2Handler':init/2 line 42 in 'Elixir.Phoenix.Endpoint.Cowboy2Handler':init/2 line 42
2019-11-18 23:15:05.909 [error] <0.475.0> Lager event handler error_logger_lager_h exited with reason {'EXIT',{{case_clause,['Elixir.SignallingWeb.Endpoint.HTTP',<0.1840.0>,1,<0.1841.0>,{{#{'__exception__' => true,'__struct__' => 'Elixir.FunctionClauseError',args => nil,arity => 2,clauses => nil,function => sdp_call,kind => nil,module => 'Elixir.Signalling.Notifier'},[{'Elixir.Signalling.Notifier',sdp_call,[[#{'__meta__' => #{'__struct__' => 'Elixir.Ecto.Schema.Metadata',context => nil,prefix => nil,schema => 'Elixir.Domoapi.People.Tenant',source => <<"tenants">>,state => loaded},'__struct__' => ...,...},...],...],...},...]},...},...]},...}}
2019-11-18 23:15:06.461 [error] <0.1845.0> CRASH REPORT Process <0.1845.0> with 0 neighbours exited with reason: {{#{'__exception__' => true,'__struct__' => 'Elixir.FunctionClauseError',args => nil,arity => 2,clauses => nil,function => sdp_call,kind => nil,module => 'Elixir.Signalling.Notifier'},[{'Elixir.Signalling.Notifier',sdp_call,[[#{'__meta__' => #{'__struct__' => 'Elixir.Ecto.Schema.Metadata',context => nil,prefix => nil,schema => 'Elixir.Domoapi.People.Tenant',source => <<"tenants">>,state => loaded},'__struct__' => 'Elixir.Domoapi.People.Tenant',apartment => #{'__cardinality__' => one,'__field__' => ...,...},...},...],...],...},...]},...} in 'Elixir.Phoenix.Endpoint.Cowboy2Handler':init/2 line 42 in 'Elixir.Phoenix.Endpoint.Cowboy2Handler':init/2 line 42
2019-11-18 23:15:06.470 [error] <0.475.0> Lager event handler error_logger_lager_h exited with reason {'EXIT',{{case_clause,['Elixir.SignallingWeb.Endpoint.HTTP',<0.1844.0>,1,<0.1845.0>,{{#{'__exception__' => true,'__struct__' => 'Elixir.FunctionClauseError',args => nil,arity => 2,clauses => nil,function => sdp_call,kind => nil,module => 'Elixir.Signalling.Notifier'},[{'Elixir.Signalling.Notifier',sdp_call,[[#{'__meta__' => #{'__struct__' => 'Elixir.Ecto.Schema.Metadata',context => nil,prefix => nil,schema => 'Elixir.Domoapi.People.Tenant',source => <<"tenants">>,state => loaded},'__struct__' => ...,...},...],...],...},...]},...},...]},...}}
2019-11-18 23:16:09.725 [error] <0.1898.0> CRASH REPORT Process <0.1898.0> with 0 neighbours exited with reason: {{#{'__exception__' => true,'__struct__' => 'Elixir.FunctionClauseError',args => nil,arity => 2,clauses => nil,function => sdp_call,kind => nil,module => 'Elixir.Signalling.Notifier'},[{'Elixir.Signalling.Notifier',sdp_call,[[#{'__meta__' => #{'__struct__' => 'Elixir.Ecto.Schema.Metadata',context => nil,prefix => nil,schema => 'Elixir.Domoapi.People.Tenant',source => <<"tenants">>,state => loaded},'__struct__' => 'Elixir.Domoapi.People.Tenant',apartment => #{'__cardinality__' => one,'__field__' => ...,...},...},...],...],...},...]},...} in 'Elixir.Phoenix.Endpoint.Cowboy2Handler':init/2 line 42 in 'Elixir.Phoenix.Endpoint.Cowboy2Handler':init/2 line 42
2019-11-18 23:16:09.734 [error] <0.475.0> Lager event handler error_logger_lager_h exited with reason {'EXIT',{{case_clause,['Elixir.SignallingWeb.Endpoint.HTTP',<0.1897.0>,1,<0.1898.0>,{{#{'__exception__' => true,'__struct__' => 'Elixir.FunctionClauseError',args => nil,arity => 2,clauses => nil,function => sdp_call,kind => nil,module => 'Elixir.Signalling.Notifier'},[{'Elixir.Signalling.Notifier',sdp_call,[[#{'__meta__' => #{'__struct__' => 'Elixir.Ecto.Schema.Metadata',context => nil,prefix => nil,schema => 'Elixir.Domoapi.People.Tenant',source => <<"tenants">>,state => loaded},'__struct__' => ...,...},...],...],...},...]},...},...]},...}}
2019-11-18 23:16:10.273 [error] <0.1902.0> CRASH REPORT Process <0.1902.0> with 0 neighbours exited with reason: {{#{'__exception__' => true,'__struct__' => 'Elixir.FunctionClauseError',args => nil,arity => 2,clauses => nil,function => sdp_call,kind => nil,module => 'Elixir.Signalling.Notifier'},[{'Elixir.Signalling.Notifier',sdp_call,[[#{'__meta__' => #{'__struct__' => 'Elixir.Ecto.Schema.Metadata',context => nil,prefix => nil,schema => 'Elixir.Domoapi.People.Tenant',source => <<"tenants">>,state => loaded},'__struct__' => 'Elixir.Domoapi.People.Tenant',apartment => #{'__cardinality__' => one,'__field__' => ...,...},...},...],...],...},...]},...} in 'Elixir.Phoenix.Endpoint.Cowboy2Handler':init/2 line 42 in 'Elixir.Phoenix.Endpoint.Cowboy2Handler':init/2 line 42
2019-11-18 23:16:10.282 [error] <0.475.0> Lager event handler error_logger_lager_h exited with reason {'EXIT',{{case_clause,['Elixir.SignallingWeb.Endpoint.HTTP',<0.1901.0>,1,<0.1902.0>,{{#{'__exception__' => true,'__struct__' => 'Elixir.FunctionClauseError',args => nil,arity => 2,clauses => nil,function => sdp_call,kind => nil,module => 'Elixir.Signalling.Notifier'},[{'Elixir.Signalling.Notifier',sdp_call,[[#{'__meta__' => #{'__struct__' => 'Elixir.Ecto.Schema.Metadata',context => nil,prefix => nil,schema => 'Elixir.Domoapi.People.Tenant',source => <<"tenants">>,state => loaded},'__struct__' => ...,...},...],...],...},...]},...},...]},...}}
2019-11-18 23:16:10.875 [error] <0.1906.0> CRASH REPORT Process <0.1906.0> with 0 neighbours exited with reason: {{#{'__exception__' => true,'__struct__' => 'Elixir.FunctionClauseError',args => nil,arity => 2,clauses => nil,function => sdp_call,kind => nil,module => 'Elixir.Signalling.Notifier'},[{'Elixir.Signalling.Notifier',sdp_call,[[#{'__meta__' => #{'__struct__' => 'Elixir.Ecto.Schema.Metadata',context => nil,prefix => nil,schema => 'Elixir.Domoapi.People.Tenant',source => <<"tenants">>,state => loaded},'__struct__' => 'Elixir.Domoapi.People.Tenant',apartment => #{'__cardinality__' => one,'__field__' => ...,...},...},...],...],...},...]},...} in 'Elixir.Phoenix.Endpoint.Cowboy2Handler':init/2 line 42 in 'Elixir.Phoenix.Endpoint.Cowboy2Handler':init/2 line 42
2019-11-18 23:16:10.884 [error] <0.475.0> Lager event handler error_logger_lager_h exited with reason {'EXIT',{{case_clause,['Elixir.SignallingWeb.Endpoint.HTTP',<0.1905.0>,1,<0.1906.0>,{{#{'__exception__' => true,'__struct__' => 'Elixir.FunctionClauseError',args => nil,arity => 2,clauses => nil,function => sdp_call,kind => nil,module => 'Elixir.Signalling.Notifier'},[{'Elixir.Signalling.Notifier',sdp_call,[[#{'__meta__' => #{'__struct__' => 'Elixir.Ecto.Schema.Metadata',context => nil,prefix => nil,schema => 'Elixir.Domoapi.People.Tenant',source => <<"tenants">>,state => loaded},'__struct__' => ...,...},...],...],...},...]},...},...]},...}}
2019-11-18 23:17:01.635 [error] <0.1959.0> CRASH REPORT Process <0.1959.0> with 0 neighbours exited with reason: {{#{'__exception__' => true,'__struct__' => 'Elixir.FunctionClauseError',args => nil,arity => 2,clauses => nil,function => sdp_call,kind => nil,module => 'Elixir.Signalling.Notifier'},[{'Elixir.Signalling.Notifier',sdp_call,[[#{'__meta__' => #{'__struct__' => 'Elixir.Ecto.Schema.Metadata',context => nil,prefix => nil,schema => 'Elixir.Domoapi.People.Tenant',source => <<"tenants">>,state => loaded},'__struct__' => 'Elixir.Domoapi.People.Tenant',apartment => #{'__cardinality__' => one,'__field__' => ...,...},...},...],...],...},...]},...} in 'Elixir.Phoenix.Endpoint.Cowboy2Handler':init/2 line 42 in 'Elixir.Phoenix.Endpoint.Cowboy2Handler':init/2 line 42
2019-11-18 23:17:01.643 [error] <0.475.0> Lager event handler error_logger_lager_h exited with reason {'EXIT',{{case_clause,['Elixir.SignallingWeb.Endpoint.HTTP',<0.1958.0>,1,<0.1959.0>,{{#{'__exception__' => true,'__struct__' => 'Elixir.FunctionClauseError',args => nil,arity => 2,clauses => nil,function => sdp_call,kind => nil,module => 'Elixir.Signalling.Notifier'},[{'Elixir.Signalling.Notifier',sdp_call,[[#{'__meta__' => #{'__struct__' => 'Elixir.Ecto.Schema.Metadata',context => nil,prefix => nil,schema => 'Elixir.Domoapi.People.Tenant',source => <<"tenants">>,state => loaded},'__struct__' => ...,...},...],...],...},...]},...},...]},...}}
2019-11-18 23:17:42.328 [error] <0.1995.0> CRASH REPORT Process <0.1995.0> with 0 neighbours exited with reason: {{#{'__exception__' => true,'__struct__' => 'Elixir.BadFunctionError',term => #{'__exception__' => true,'__struct__' => 'Elixir.Phoenix.ActionClauseError',args => [#{'__struct__' => 'Elixir.Plug.Conn',adapter => {'Elixir.Plug.Cowboy.Conn',#{bindings => #{},body_length => 15,cert => undefined,has_body => true,has_read_body => true,headers => #{<<"accept-charset">> => <<"UTF-8">>,<<"accept-encoding">> => <<"gzip">>,<<"connection">> => <<"upgrade">>,<<"content-length">> => <<"15">>,<<"...">> => ...,...},...}},...},...],...}},...},...} in 'Elixir.Phoenix.Endpoint.Cowboy2Handler':init/2 line 42 in 'Elixir.Phoenix.Endpoint.Cowboy2Handler':init/2 line 42
2019-11-18 23:17:42.336 [error] <0.475.0> Lager event handler error_logger_lager_h exited with reason {'EXIT',{{case_clause,['Elixir.SignallingWeb.Endpoint.HTTP',<0.1994.0>,1,<0.1995.0>,{{#{'__exception__' => true,'__struct__' => 'Elixir.BadFunctionError',term => #{'__exception__' => true,'__struct__' => 'Elixir.Phoenix.ActionClauseError',args => [#{'__struct__' => 'Elixir.Plug.Conn',adapter => {'Elixir.Plug.Cowboy.Conn',#{bindings => #{},body_length => 15,cert => undefined,has_body => true,has_read_body => true,headers => #{<<"accept-charset">> => <<"UTF-8">>,<<"accept-encoding">> => <<...>>,...},...}},...},...],...}},...},...},...]},...}}
2019-11-18 23:18:17.743 [error] <0.2042.0> CRASH REPORT Process <0.2042.0> with 0 neighbours exited with reason: {{#{'__exception__' => true,'__struct__' => 'Elixir.FunctionClauseError',args => nil,arity => 2,clauses => nil,function => sdp_call,kind => nil,module => 'Elixir.Signalling.Notifier'},[{'Elixir.Signalling.Notifier',sdp_call,[[#{'__meta__' => #{'__struct__' => 'Elixir.Ecto.Schema.Metadata',context => nil,prefix => nil,schema => 'Elixir.Domoapi.People.Tenant',source => <<"tenants">>,state => loaded},'__struct__' => 'Elixir.Domoapi.People.Tenant',apartment => #{'__cardinality__' => one,'__field__' => ...,...},...},...],...],...},...]},...} in 'Elixir.Phoenix.Endpoint.Cowboy2Handler':init/2 line 42 in 'Elixir.Phoenix.Endpoint.Cowboy2Handler':init/2 line 42
2019-11-18 23:18:17.751 [error] <0.475.0> Lager event handler error_logger_lager_h exited with reason {'EXIT',{{case_clause,['Elixir.SignallingWeb.Endpoint.HTTP',<0.2041.0>,1,<0.2042.0>,{{#{'__exception__' => true,'__struct__' => 'Elixir.FunctionClauseError',args => nil,arity => 2,clauses => nil,function => sdp_call,kind => nil,module => 'Elixir.Signalling.Notifier'},[{'Elixir.Signalling.Notifier',sdp_call,[[#{'__meta__' => #{'__struct__' => 'Elixir.Ecto.Schema.Metadata',context => nil,prefix => nil,schema => 'Elixir.Domoapi.People.Tenant',source => <<"tenants">>,state => loaded},'__struct__' => ...,...},...],...],...},...]},...},...]},...}}
2019-11-18 23:22:31.002 [error] <0.2113.0> CRASH REPORT Process <0.2113.0> with 0 neighbours exited with reason: {{#{'__exception__' => true,'__struct__' => 'Elixir.FunctionClauseError',args => nil,arity => 2,clauses => nil,function => sdp_call,kind => nil,module => 'Elixir.Signalling.Notifier'},[{'Elixir.Signalling.Notifier',sdp_call,[[#{'__meta__' => #{'__struct__' => 'Elixir.Ecto.Schema.Metadata',context => nil,prefix => nil,schema => 'Elixir.Domoapi.People.Tenant',source => <<"tenants">>,state => loaded},'__struct__' => 'Elixir.Domoapi.People.Tenant',apartment => #{'__cardinality__' => one,'__field__' => ...,...},...},...],...],...},...]},...} in 'Elixir.Phoenix.Endpoint.Cowboy2Handler':init/2 line 42 in 'Elixir.Phoenix.Endpoint.Cowboy2Handler':init/2 line 42
2019-11-18 23:22:31.592 [error] <0.2116.0> CRASH REPORT Process <0.2116.0> with 0 neighbours exited with reason: {{#{'__exception__' => true,'__struct__' => 'Elixir.FunctionClauseError',args => nil,arity => 2,clauses => nil,function => sdp_call,kind => nil,module => 'Elixir.Signalling.Notifier'},[{'Elixir.Signalling.Notifier',sdp_call,[[#{'__meta__' => #{'__struct__' => 'Elixir.Ecto.Schema.Metadata',context => nil,prefix => nil,schema => 'Elixir.Domoapi.People.Tenant',source => <<"tenants">>,state => loaded},'__struct__' => 'Elixir.Domoapi.People.Tenant',apartment => #{'__cardinality__' => one,'__field__' => ...,...},...},...],...],...},...]},...} in 'Elixir.Phoenix.Endpoint.Cowboy2Handler':init/2 line 42 in 'Elixir.Phoenix.Endpoint.Cowboy2Handler':init/2 line 42
2019-11-18 23:22:31.601 [error] <0.475.0> Lager event handler error_logger_lager_h exited with reason {'EXIT',{{case_clause,['Elixir.SignallingWeb.Endpoint.HTTP',<0.2115.0>,1,<0.2116.0>,{{#{'__exception__' => true,'__struct__' => 'Elixir.FunctionClauseError',args => nil,arity => 2,clauses => nil,function => sdp_call,kind => nil,module => 'Elixir.Signalling.Notifier'},[{'Elixir.Signalling.Notifier',sdp_call,[[#{'__meta__' => #{'__struct__' => 'Elixir.Ecto.Schema.Metadata',context => nil,prefix => nil,schema => 'Elixir.Domoapi.People.Tenant',source => <<"tenants">>,state => loaded},'__struct__' => ...,...},...],...],...},...]},...},...]},...}}
2019-11-18 23:22:32.256 [error] <0.2120.0> CRASH REPORT Process <0.2120.0> with 0 neighbours exited with reason: {{#{'__exception__' => true,'__struct__' => 'Elixir.FunctionClauseError',args => nil,arity => 2,clauses => nil,function => sdp_call,kind => nil,module => 'Elixir.Signalling.Notifier'},[{'Elixir.Signalling.Notifier',sdp_call,[[#{'__meta__' => #{'__struct__' => 'Elixir.Ecto.Schema.Metadata',context => nil,prefix => nil,schema => 'Elixir.Domoapi.People.Tenant',source => <<"tenants">>,state => loaded},'__struct__' => 'Elixir.Domoapi.People.Tenant',apartment => #{'__cardinality__' => one,'__field__' => ...,...},...},...],...],...},...]},...} in 'Elixir.Phoenix.Endpoint.Cowboy2Handler':init/2 line 42 in 'Elixir.Phoenix.Endpoint.Cowboy2Handler':init/2 line 42
2019-11-18 23:22:32.265 [error] <0.475.0> Lager event handler error_logger_lager_h exited with reason {'EXIT',{{case_clause,['Elixir.SignallingWeb.Endpoint.HTTP',<0.2119.0>,1,<0.2120.0>,{{#{'__exception__' => true,'__struct__' => 'Elixir.FunctionClauseError',args => nil,arity => 2,clauses => nil,function => sdp_call,kind => nil,module => 'Elixir.Signalling.Notifier'},[{'Elixir.Signalling.Notifier',sdp_call,[[#{'__meta__' => #{'__struct__' => 'Elixir.Ecto.Schema.Metadata',context => nil,prefix => nil,schema => 'Elixir.Domoapi.People.Tenant',source => <<"tenants">>,state => loaded},'__struct__' => ...,...},...],...],...},...]},...},...]},...}}
2019-11-18 23:33:40.056 [error] <0.1188.0>@Elixir.Archive.VideoVisor:create_dir:59 CRASH REPORT Process <0.1188.0> with 0 neighbours crashed with reason: bad argument in 'Elixir.Archive.VideoVisor':create_dir/2 line 59
2019-11-18 23:34:07.745 [error] <0.1363.0> CRASH REPORT Process <0.1363.0> with 0 neighbours exited with reason: {{#{'__exception__' => true,'__struct__' => 'Elixir.FunctionClauseError',args => nil,arity => 2,clauses => nil,function => sdp_call,kind => nil,module => 'Elixir.Signalling.Notifier'},[{'Elixir.Signalling.Notifier',sdp_call,[[#{'__meta__' => #{'__struct__' => 'Elixir.Ecto.Schema.Metadata',context => nil,prefix => nil,schema => 'Elixir.Domoapi.People.Tenant',source => <<"tenants">>,state => loaded},'__struct__' => 'Elixir.Domoapi.People.Tenant',apartment => #{'__cardinality__' => one,'__field__' => ...,...},...},...],...],...},...]},...} in 'Elixir.Phoenix.Endpoint.Cowboy2Handler':init/2 line 42 in 'Elixir.Phoenix.Endpoint.Cowboy2Handler':init/2 line 42
2019-11-18 23:34:07.776 [error] <0.460.0> Lager event handler error_logger_lager_h exited with reason {'EXIT',{{case_clause,['Elixir.SignallingWeb.Endpoint.HTTP',<0.1362.0>,1,<0.1363.0>,{{#{'__exception__' => true,'__struct__' => 'Elixir.FunctionClauseError',args => nil,arity => 2,clauses => nil,function => sdp_call,kind => nil,module => 'Elixir.Signalling.Notifier'},[{'Elixir.Signalling.Notifier',sdp_call,[[#{'__meta__' => #{'__struct__' => 'Elixir.Ecto.Schema.Metadata',context => nil,prefix => nil,schema => 'Elixir.Domoapi.People.Tenant',source => <<"tenants">>,state => loaded},'__struct__' => ...,...},...],...],...},...]},...},...]},...}}
2019-11-18 23:34:08.324 [error] <0.1367.0> CRASH REPORT Process <0.1367.0> with 0 neighbours exited with reason: {{#{'__exception__' => true,'__struct__' => 'Elixir.FunctionClauseError',args => nil,arity => 2,clauses => nil,function => sdp_call,kind => nil,module => 'Elixir.Signalling.Notifier'},[{'Elixir.Signalling.Notifier',sdp_call,[[#{'__meta__' => #{'__struct__' => 'Elixir.Ecto.Schema.Metadata',context => nil,prefix => nil,schema => 'Elixir.Domoapi.People.Tenant',source => <<"tenants">>,state => loaded},'__struct__' => 'Elixir.Domoapi.People.Tenant',apartment => #{'__cardinality__' => one,'__field__' => ...,...},...},...],...],...},...]},...} in 'Elixir.Phoenix.Endpoint.Cowboy2Handler':init/2 line 42 in 'Elixir.Phoenix.Endpoint.Cowboy2Handler':init/2 line 42
2019-11-18 23:34:08.332 [error] <0.460.0> Lager event handler error_logger_lager_h exited with reason {'EXIT',{{case_clause,['Elixir.SignallingWeb.Endpoint.HTTP',<0.1366.0>,1,<0.1367.0>,{{#{'__exception__' => true,'__struct__' => 'Elixir.FunctionClauseError',args => nil,arity => 2,clauses => nil,function => sdp_call,kind => nil,module => 'Elixir.Signalling.Notifier'},[{'Elixir.Signalling.Notifier',sdp_call,[[#{'__meta__' => #{'__struct__' => 'Elixir.Ecto.Schema.Metadata',context => nil,prefix => nil,schema => 'Elixir.Domoapi.People.Tenant',source => <<"tenants">>,state => loaded},'__struct__' => ...,...},...],...],...},...]},...},...]},...}}
2019-11-18 23:34:08.931 [error] <0.1371.0> CRASH REPORT Process <0.1371.0> with 0 neighbours exited with reason: {{#{'__exception__' => true,'__struct__' => 'Elixir.FunctionClauseError',args => nil,arity => 2,clauses => nil,function => sdp_call,kind => nil,module => 'Elixir.Signalling.Notifier'},[{'Elixir.Signalling.Notifier',sdp_call,[[#{'__meta__' => #{'__struct__' => 'Elixir.Ecto.Schema.Metadata',context => nil,prefix => nil,schema => 'Elixir.Domoapi.People.Tenant',source => <<"tenants">>,state => loaded},'__struct__' => 'Elixir.Domoapi.People.Tenant',apartment => #{'__cardinality__' => one,'__field__' => ...,...},...},...],...],...},...]},...} in 'Elixir.Phoenix.Endpoint.Cowboy2Handler':init/2 line 42 in 'Elixir.Phoenix.Endpoint.Cowboy2Handler':init/2 line 42
2019-11-18 23:34:08.938 [error] <0.460.0> Lager event handler error_logger_lager_h exited with reason {'EXIT',{{case_clause,['Elixir.SignallingWeb.Endpoint.HTTP',<0.1370.0>,1,<0.1371.0>,{{#{'__exception__' => true,'__struct__' => 'Elixir.FunctionClauseError',args => nil,arity => 2,clauses => nil,function => sdp_call,kind => nil,module => 'Elixir.Signalling.Notifier'},[{'Elixir.Signalling.Notifier',sdp_call,[[#{'__meta__' => #{'__struct__' => 'Elixir.Ecto.Schema.Metadata',context => nil,prefix => nil,schema => 'Elixir.Domoapi.People.Tenant',source => <<"tenants">>,state => loaded},'__struct__' => ...,...},...],...],...},...]},...},...]},...}}
2019-11-18 23:35:45.402 [error] <0.1423.0> CRASH REPORT Process <0.1423.0> with 0 neighbours exited with reason: {{#{'__exception__' => true,'__struct__' => 'Elixir.FunctionClauseError',args => nil,arity => 2,clauses => nil,function => sdp_call,kind => nil,module => 'Elixir.Signalling.Notifier'},[{'Elixir.Signalling.Notifier',sdp_call,[[#{'__meta__' => #{'__struct__' => 'Elixir.Ecto.Schema.Metadata',context => nil,prefix => nil,schema => 'Elixir.Domoapi.People.Tenant',source => <<"tenants">>,state => loaded},'__struct__' => 'Elixir.Domoapi.People.Tenant',apartment => #{'__cardinality__' => one,'__field__' => ...,...},...},...],...],...},...]},...} in 'Elixir.Phoenix.Endpoint.Cowboy2Handler':init/2 line 42 in 'Elixir.Phoenix.Endpoint.Cowboy2Handler':init/2 line 42
2019-11-18 23:35:45.411 [error] <0.460.0> Lager event handler error_logger_lager_h exited with reason {'EXIT',{{case_clause,['Elixir.SignallingWeb.Endpoint.HTTP',<0.1422.0>,1,<0.1423.0>,{{#{'__exception__' => true,'__struct__' => 'Elixir.FunctionClauseError',args => nil,arity => 2,clauses => nil,function => sdp_call,kind => nil,module => 'Elixir.Signalling.Notifier'},[{'Elixir.Signalling.Notifier',sdp_call,[[#{'__meta__' => #{'__struct__' => 'Elixir.Ecto.Schema.Metadata',context => nil,prefix => nil,schema => 'Elixir.Domoapi.People.Tenant',source => <<"tenants">>,state => loaded},'__struct__' => ...,...},...],...],...},...]},...},...]},...}}
2019-11-18 23:35:45.979 [error] <0.1427.0> CRASH REPORT Process <0.1427.0> with 0 neighbours exited with reason: {{#{'__exception__' => true,'__struct__' => 'Elixir.FunctionClauseError',args => nil,arity => 2,clauses => nil,function => sdp_call,kind => nil,module => 'Elixir.Signalling.Notifier'},[{'Elixir.Signalling.Notifier',sdp_call,[[#{'__meta__' => #{'__struct__' => 'Elixir.Ecto.Schema.Metadata',context => nil,prefix => nil,schema => 'Elixir.Domoapi.People.Tenant',source => <<"tenants">>,state => loaded},'__struct__' => 'Elixir.Domoapi.People.Tenant',apartment => #{'__cardinality__' => one,'__field__' => ...,...},...},...],...],...},...]},...} in 'Elixir.Phoenix.Endpoint.Cowboy2Handler':init/2 line 42 in 'Elixir.Phoenix.Endpoint.Cowboy2Handler':init/2 line 42
2019-11-18 23:35:45.986 [error] <0.460.0> Lager event handler error_logger_lager_h exited with reason {'EXIT',{{case_clause,['Elixir.SignallingWeb.Endpoint.HTTP',<0.1426.0>,1,<0.1427.0>,{{#{'__exception__' => true,'__struct__' => 'Elixir.FunctionClauseError',args => nil,arity => 2,clauses => nil,function => sdp_call,kind => nil,module => 'Elixir.Signalling.Notifier'},[{'Elixir.Signalling.Notifier',sdp_call,[[#{'__meta__' => #{'__struct__' => 'Elixir.Ecto.Schema.Metadata',context => nil,prefix => nil,schema => 'Elixir.Domoapi.People.Tenant',source => <<"tenants">>,state => loaded},'__struct__' => ...,...},...],...],...},...]},...},...]},...}}
2019-11-18 23:35:46.560 [error] <0.1431.0> CRASH REPORT Process <0.1431.0> with 0 neighbours exited with reason: {{#{'__exception__' => true,'__struct__' => 'Elixir.FunctionClauseError',args => nil,arity => 2,clauses => nil,function => sdp_call,kind => nil,module => 'Elixir.Signalling.Notifier'},[{'Elixir.Signalling.Notifier',sdp_call,[[#{'__meta__' => #{'__struct__' => 'Elixir.Ecto.Schema.Metadata',context => nil,prefix => nil,schema => 'Elixir.Domoapi.People.Tenant',source => <<"tenants">>,state => loaded},'__struct__' => 'Elixir.Domoapi.People.Tenant',apartment => #{'__cardinality__' => one,'__field__' => ...,...},...},...],...],...},...]},...} in 'Elixir.Phoenix.Endpoint.Cowboy2Handler':init/2 line 42 in 'Elixir.Phoenix.Endpoint.Cowboy2Handler':init/2 line 42
2019-11-18 23:35:46.569 [error] <0.460.0> Lager event handler error_logger_lager_h exited with reason {'EXIT',{{case_clause,['Elixir.SignallingWeb.Endpoint.HTTP',<0.1430.0>,1,<0.1431.0>,{{#{'__exception__' => true,'__struct__' => 'Elixir.FunctionClauseError',args => nil,arity => 2,clauses => nil,function => sdp_call,kind => nil,module => 'Elixir.Signalling.Notifier'},[{'Elixir.Signalling.Notifier',sdp_call,[[#{'__meta__' => #{'__struct__' => 'Elixir.Ecto.Schema.Metadata',context => nil,prefix => nil,schema => 'Elixir.Domoapi.People.Tenant',source => <<"tenants">>,state => loaded},'__struct__' => ...,...},...],...],...},...]},...},...]},...}}
2019-11-18 23:40:43.662 [error] <0.520.0> Failed to start Ranch listener 'Elixir.DomoapiUserWeb.Endpoint.HTTP' in ranch_tcp:listen([{cacerts,'...'},{key,'...'},{cert,'...'},{port,9080}]) for reason eaddrinuse (address already in use)
2019-11-18 23:40:43.687 [error] <0.518.0> Supervisor {<0.518.0>,ranch_listener_sup} had child ranch_acceptors_sup started with ranch_acceptors_sup:start_link('Elixir.DomoapiUserWeb.Endpoint.HTTP', ranch_tcp) at undefined exit with reason {listen_error,'Elixir.DomoapiUserWeb.Endpoint.HTTP',eaddrinuse} in context start_error
2019-11-18 23:40:43.687 [error] <0.520.0> CRASH REPORT Process <0.520.0> with 0 neighbours exited with reason: {listen_error,'Elixir.DomoapiUserWeb.Endpoint.HTTP',eaddrinuse} in ranch_acceptors_sup:listen_error/5 line 66
2019-11-18 23:40:43.687 [error] <0.499.0> Supervisor 'Elixir.DomoapiUserWeb.Endpoint' had child {ranch_listener_sup,'Elixir.DomoapiUserWeb.Endpoint.HTTP'} started with 'Elixir.Phoenix.Endpoint.Cowboy2Adapter':start_link(http, 'Elixir.DomoapiUserWeb.Endpoint', {ranch_listener_sup,start_link,['Elixir.DomoapiUserWeb.Endpoint.HTTP',ranch_tcp,#{max_connections => ...,...},...]}) at undefined exit with reason {shutdown,{failed_to_start_child,ranch_acceptors_sup,{listen_error,'Elixir.DomoapiUserWeb.Endpoint.HTTP',eaddrinuse}}} in context start_error
2019-11-18 23:47:06.323 [error] <0.1567.0> CRASH REPORT Process <0.1567.0> with 0 neighbours exited with reason: {{#{'__exception__' => true,'__struct__' => 'Elixir.FunctionClauseError',args => nil,arity => 2,clauses => nil,function => sdp_call,kind => nil,module => 'Elixir.Signalling.Notifier'},[{'Elixir.Signalling.Notifier',sdp_call,[[#{'__meta__' => #{'__struct__' => 'Elixir.Ecto.Schema.Metadata',context => nil,prefix => nil,schema => 'Elixir.Domoapi.People.Tenant',source => <<"tenants">>,state => loaded},'__struct__' => 'Elixir.Domoapi.People.Tenant',apartment => #{'__cardinality__' => one,'__field__' => ...,...},...},...],...],...},...]},...} in 'Elixir.Phoenix.Endpoint.Cowboy2Handler':init/2 line 42 in 'Elixir.Phoenix.Endpoint.Cowboy2Handler':init/2 line 42
2019-11-18 23:47:06.331 [error] <0.460.0> Lager event handler error_logger_lager_h exited with reason {'EXIT',{{case_clause,['Elixir.SignallingWeb.Endpoint.HTTP',<0.1566.0>,1,<0.1567.0>,{{#{'__exception__' => true,'__struct__' => 'Elixir.FunctionClauseError',args => nil,arity => 2,clauses => nil,function => sdp_call,kind => nil,module => 'Elixir.Signalling.Notifier'},[{'Elixir.Signalling.Notifier',sdp_call,[[#{'__meta__' => #{'__struct__' => 'Elixir.Ecto.Schema.Metadata',context => nil,prefix => nil,schema => 'Elixir.Domoapi.People.Tenant',source => <<"tenants">>,state => loaded},'__struct__' => ...,...},...],...],...},...]},...},...]},...}}
2019-11-18 23:47:07.334 [error] <0.1571.0> CRASH REPORT Process <0.1571.0> with 0 neighbours exited with reason: {{#{'__exception__' => true,'__struct__' => 'Elixir.FunctionClauseError',args => nil,arity => 2,clauses => nil,function => sdp_call,kind => nil,module => 'Elixir.Signalling.Notifier'},[{'Elixir.Signalling.Notifier',sdp_call,[[#{'__meta__' => #{'__struct__' => 'Elixir.Ecto.Schema.Metadata',context => nil,prefix => nil,schema => 'Elixir.Domoapi.People.Tenant',source => <<"tenants">>,state => loaded},'__struct__' => 'Elixir.Domoapi.People.Tenant',apartment => #{'__cardinality__' => one,'__field__' => ...,...},...},...],...],...},...]},...} in 'Elixir.Phoenix.Endpoint.Cowboy2Handler':init/2 line 42 in 'Elixir.Phoenix.Endpoint.Cowboy2Handler':init/2 line 42
2019-11-18 23:47:07.341 [error] <0.460.0> Lager event handler error_logger_lager_h exited with reason {'EXIT',{{case_clause,['Elixir.SignallingWeb.Endpoint.HTTP',<0.1570.0>,1,<0.1571.0>,{{#{'__exception__' => true,'__struct__' => 'Elixir.FunctionClauseError',args => nil,arity => 2,clauses => nil,function => sdp_call,kind => nil,module => 'Elixir.Signalling.Notifier'},[{'Elixir.Signalling.Notifier',sdp_call,[[#{'__meta__' => #{'__struct__' => 'Elixir.Ecto.Schema.Metadata',context => nil,prefix => nil,schema => 'Elixir.Domoapi.People.Tenant',source => <<"tenants">>,state => loaded},'__struct__' => ...,...},...],...],...},...]},...},...]},...}}
2019-11-18 23:47:07.918 [error] <0.1575.0> CRASH REPORT Process <0.1575.0> with 0 neighbours exited with reason: {{#{'__exception__' => true,'__struct__' => 'Elixir.FunctionClauseError',args => nil,arity => 2,clauses => nil,function => sdp_call,kind => nil,module => 'Elixir.Signalling.Notifier'},[{'Elixir.Signalling.Notifier',sdp_call,[[#{'__meta__' => #{'__struct__' => 'Elixir.Ecto.Schema.Metadata',context => nil,prefix => nil,schema => 'Elixir.Domoapi.People.Tenant',source => <<"tenants">>,state => loaded},'__struct__' => 'Elixir.Domoapi.People.Tenant',apartment => #{'__cardinality__' => one,'__field__' => ...,...},...},...],...],...},...]},...} in 'Elixir.Phoenix.Endpoint.Cowboy2Handler':init/2 line 42 in 'Elixir.Phoenix.Endpoint.Cowboy2Handler':init/2 line 42
2019-11-18 23:47:07.927 [error] <0.460.0> Lager event handler error_logger_lager_h exited with reason {'EXIT',{{case_clause,['Elixir.SignallingWeb.Endpoint.HTTP',<0.1574.0>,1,<0.1575.0>,{{#{'__exception__' => true,'__struct__' => 'Elixir.FunctionClauseError',args => nil,arity => 2,clauses => nil,function => sdp_call,kind => nil,module => 'Elixir.Signalling.Notifier'},[{'Elixir.Signalling.Notifier',sdp_call,[[#{'__meta__' => #{'__struct__' => 'Elixir.Ecto.Schema.Metadata',context => nil,prefix => nil,schema => 'Elixir.Domoapi.People.Tenant',source => <<"tenants">>,state => loaded},'__struct__' => ...,...},...],...],...},...]},...},...]},...}}
2019-11-18 23:50:20.013 [error] <0.1184.0>@Elixir.Archive.VideoVisor:create_dir:59 CRASH REPORT Process <0.1184.0> with 0 neighbours crashed with reason: bad argument in 'Elixir.Archive.VideoVisor':create_dir/2 line 59
2019-11-18 23:50:42.210 [error] <0.1357.0> CRASH REPORT Process <0.1357.0> with 0 neighbours exited with reason: {{#{'__exception__' => true,'__struct__' => 'Elixir.FunctionClauseError',args => nil,arity => 2,clauses => nil,function => sdp_call,kind => nil,module => 'Elixir.Signalling.Notifier'},[{'Elixir.Signalling.Notifier',sdp_call,[[#{'__meta__' => #{'__struct__' => 'Elixir.Ecto.Schema.Metadata',context => nil,prefix => nil,schema => 'Elixir.Domoapi.People.Tenant',source => <<"tenants">>,state => loaded},'__struct__' => 'Elixir.Domoapi.People.Tenant',apartment => #{'__cardinality__' => one,'__field__' => ...,...},...},...],...],...},...]},...} in 'Elixir.Phoenix.Endpoint.Cowboy2Handler':init/2 line 42 in 'Elixir.Phoenix.Endpoint.Cowboy2Handler':init/2 line 42
2019-11-18 23:50:42.247 [error] <0.455.0> Lager event handler error_logger_lager_h exited with reason {'EXIT',{{case_clause,['Elixir.SignallingWeb.Endpoint.HTTP',<0.1356.0>,1,<0.1357.0>,{{#{'__exception__' => true,'__struct__' => 'Elixir.FunctionClauseError',args => nil,arity => 2,clauses => nil,function => sdp_call,kind => nil,module => 'Elixir.Signalling.Notifier'},[{'Elixir.Signalling.Notifier',sdp_call,[[#{'__meta__' => #{'__struct__' => 'Elixir.Ecto.Schema.Metadata',context => nil,prefix => nil,schema => 'Elixir.Domoapi.People.Tenant',source => <<"tenants">>,state => loaded},'__struct__' => ...,...},...],...],...},...]},...},...]},...}}
2019-11-18 23:50:42.847 [error] <0.1361.0> CRASH REPORT Process <0.1361.0> with 0 neighbours exited with reason: {{#{'__exception__' => true,'__struct__' => 'Elixir.FunctionClauseError',args => nil,arity => 2,clauses => nil,function => sdp_call,kind => nil,module => 'Elixir.Signalling.Notifier'},[{'Elixir.Signalling.Notifier',sdp_call,[[#{'__meta__' => #{'__struct__' => 'Elixir.Ecto.Schema.Metadata',context => nil,prefix => nil,schema => 'Elixir.Domoapi.People.Tenant',source => <<"tenants">>,state => loaded},'__struct__' => 'Elixir.Domoapi.People.Tenant',apartment => #{'__cardinality__' => one,'__field__' => ...,...},...},...],...],...},...]},...} in 'Elixir.Phoenix.Endpoint.Cowboy2Handler':init/2 line 42 in 'Elixir.Phoenix.Endpoint.Cowboy2Handler':init/2 line 42
2019-11-18 23:50:42.855 [error] <0.455.0> Lager event handler error_logger_lager_h exited with reason {'EXIT',{{case_clause,['Elixir.SignallingWeb.Endpoint.HTTP',<0.1360.0>,1,<0.1361.0>,{{#{'__exception__' => true,'__struct__' => 'Elixir.FunctionClauseError',args => nil,arity => 2,clauses => nil,function => sdp_call,kind => nil,module => 'Elixir.Signalling.Notifier'},[{'Elixir.Signalling.Notifier',sdp_call,[[#{'__meta__' => #{'__struct__' => 'Elixir.Ecto.Schema.Metadata',context => nil,prefix => nil,schema => 'Elixir.Domoapi.People.Tenant',source => <<"tenants">>,state => loaded},'__struct__' => ...,...},...],...],...},...]},...},...]},...}}
2019-11-18 23:50:43.470 [error] <0.1365.0> CRASH REPORT Process <0.1365.0> with 0 neighbours exited with reason: {{#{'__exception__' => true,'__struct__' => 'Elixir.FunctionClauseError',args => nil,arity => 2,clauses => nil,function => sdp_call,kind => nil,module => 'Elixir.Signalling.Notifier'},[{'Elixir.Signalling.Notifier',sdp_call,[[#{'__meta__' => #{'__struct__' => 'Elixir.Ecto.Schema.Metadata',context => nil,prefix => nil,schema => 'Elixir.Domoapi.People.Tenant',source => <<"tenants">>,state => loaded},'__struct__' => 'Elixir.Domoapi.People.Tenant',apartment => #{'__cardinality__' => one,'__field__' => ...,...},...},...],...],...},...]},...} in 'Elixir.Phoenix.Endpoint.Cowboy2Handler':init/2 line 42 in 'Elixir.Phoenix.Endpoint.Cowboy2Handler':init/2 line 42
2019-11-18 23:50:43.480 [error] <0.455.0> Lager event handler error_logger_lager_h exited with reason {'EXIT',{{case_clause,['Elixir.SignallingWeb.Endpoint.HTTP',<0.1364.0>,1,<0.1365.0>,{{#{'__exception__' => true,'__struct__' => 'Elixir.FunctionClauseError',args => nil,arity => 2,clauses => nil,function => sdp_call,kind => nil,module => 'Elixir.Signalling.Notifier'},[{'Elixir.Signalling.Notifier',sdp_call,[[#{'__meta__' => #{'__struct__' => 'Elixir.Ecto.Schema.Metadata',context => nil,prefix => nil,schema => 'Elixir.Domoapi.People.Tenant',source => <<"tenants">>,state => loaded},'__struct__' => ...,...},...],...],...},...]},...},...]},...}}
2019-11-18 23:57:25.134 [error] <0.1188.0>@Elixir.Archive.VideoVisor:create_dir:59 CRASH REPORT Process <0.1188.0> with 0 neighbours crashed with reason: bad argument in 'Elixir.Archive.VideoVisor':create_dir/2 line 59
2019-11-18 23:57:46.666 [error] <0.1362.0> CRASH REPORT Process <0.1362.0> with 0 neighbours exited with reason: {{#{'__exception__' => true,'__struct__' => 'Elixir.FunctionClauseError',args => nil,arity => 2,clauses => nil,function => sdp_call,kind => nil,module => 'Elixir.Signalling.Notifier'},[{'Elixir.Signalling.Notifier',sdp_call,[[#{'__meta__' => #{'__struct__' => 'Elixir.Ecto.Schema.Metadata',context => nil,prefix => nil,schema => 'Elixir.Domoapi.People.Tenant',source => <<"tenants">>,state => loaded},'__struct__' => 'Elixir.Domoapi.People.Tenant',apartment => #{'__cardinality__' => one,'__field__' => ...,...},...},...],...],...},...]},...} in 'Elixir.Phoenix.Endpoint.Cowboy2Handler':init/2 line 42 in 'Elixir.Phoenix.Endpoint.Cowboy2Handler':init/2 line 42
2019-11-18 23:57:46.702 [error] <0.460.0> Lager event handler error_logger_lager_h exited with reason {'EXIT',{{case_clause,['Elixir.SignallingWeb.Endpoint.HTTP',<0.1361.0>,1,<0.1362.0>,{{#{'__exception__' => true,'__struct__' => 'Elixir.FunctionClauseError',args => nil,arity => 2,clauses => nil,function => sdp_call,kind => nil,module => 'Elixir.Signalling.Notifier'},[{'Elixir.Signalling.Notifier',sdp_call,[[#{'__meta__' => #{'__struct__' => 'Elixir.Ecto.Schema.Metadata',context => nil,prefix => nil,schema => 'Elixir.Domoapi.People.Tenant',source => <<"tenants">>,state => loaded},'__struct__' => ...,...},...],...],...},...]},...},...]},...}}
2019-11-18 23:57:47.205 [error] <0.1366.0> CRASH REPORT Process <0.1366.0> with 0 neighbours exited with reason: {{#{'__exception__' => true,'__struct__' => 'Elixir.FunctionClauseError',args => nil,arity => 2,clauses => nil,function => sdp_call,kind => nil,module => 'Elixir.Signalling.Notifier'},[{'Elixir.Signalling.Notifier',sdp_call,[[#{'__meta__' => #{'__struct__' => 'Elixir.Ecto.Schema.Metadata',context => nil,prefix => nil,schema => 'Elixir.Domoapi.People.Tenant',source => <<"tenants">>,state => loaded},'__struct__' => 'Elixir.Domoapi.People.Tenant',apartment => #{'__cardinality__' => one,'__field__' => ...,...},...},...],...],...},...]},...} in 'Elixir.Phoenix.Endpoint.Cowboy2Handler':init/2 line 42 in 'Elixir.Phoenix.Endpoint.Cowboy2Handler':init/2 line 42
2019-11-18 23:57:47.214 [error] <0.460.0> Lager event handler error_logger_lager_h exited with reason {'EXIT',{{case_clause,['Elixir.SignallingWeb.Endpoint.HTTP',<0.1365.0>,1,<0.1366.0>,{{#{'__exception__' => true,'__struct__' => 'Elixir.FunctionClauseError',args => nil,arity => 2,clauses => nil,function => sdp_call,kind => nil,module => 'Elixir.Signalling.Notifier'},[{'Elixir.Signalling.Notifier',sdp_call,[[#{'__meta__' => #{'__struct__' => 'Elixir.Ecto.Schema.Metadata',context => nil,prefix => nil,schema => 'Elixir.Domoapi.People.Tenant',source => <<"tenants">>,state => loaded},'__struct__' => ...,...},...],...],...},...]},...},...]},...}}
2019-11-18 23:57:47.780 [error] <0.1370.0> CRASH REPORT Process <0.1370.0> with 0 neighbours exited with reason: {{#{'__exception__' => true,'__struct__' => 'Elixir.FunctionClauseError',args => nil,arity => 2,clauses => nil,function => sdp_call,kind => nil,module => 'Elixir.Signalling.Notifier'},[{'Elixir.Signalling.Notifier',sdp_call,[[#{'__meta__' => #{'__struct__' => 'Elixir.Ecto.Schema.Metadata',context => nil,prefix => nil,schema => 'Elixir.Domoapi.People.Tenant',source => <<"tenants">>,state => loaded},'__struct__' => 'Elixir.Domoapi.People.Tenant',apartment => #{'__cardinality__' => one,'__field__' => ...,...},...},...],...],...},...]},...} in 'Elixir.Phoenix.Endpoint.Cowboy2Handler':init/2 line 42 in 'Elixir.Phoenix.Endpoint.Cowboy2Handler':init/2 line 42
2019-11-18 23:57:47.788 [error] <0.460.0> Lager event handler error_logger_lager_h exited with reason {'EXIT',{{case_clause,['Elixir.SignallingWeb.Endpoint.HTTP',<0.1369.0>,1,<0.1370.0>,{{#{'__exception__' => true,'__struct__' => 'Elixir.FunctionClauseError',args => nil,arity => 2,clauses => nil,function => sdp_call,kind => nil,module => 'Elixir.Signalling.Notifier'},[{'Elixir.Signalling.Notifier',sdp_call,[[#{'__meta__' => #{'__struct__' => 'Elixir.Ecto.Schema.Metadata',context => nil,prefix => nil,schema => 'Elixir.Domoapi.People.Tenant',source => <<"tenants">>,state => loaded},'__struct__' => ...,...},...],...],...},...]},...},...]},...}}
2019-11-19 00:00:00.005 [error] <0.1311.0> ** Task <0.1311.0> terminating
** Started from <0.1310.0>
** When function  == #Fun<Elixir.Quantum.Executor.7.12665260>
**      arguments == []
** Reason for termination == 
** {function_clause,[{'Elixir.IO',chardata_to_string,[nil],[{file,"lib/io.ex"},{line,557}]},{'Elixir.File',ls,1,[{file,"lib/file.ex"},{line,1556}]},{'Elixir.Archive.CheckFile',check_dir,0,[{file,"lib/archive/check_file.ex"},{line,8}]},{'Elixir.Quantum.Executor','-run/4-fun-3-',3,[{file,"lib/quantum/executor.ex"},{line,141}]},{'Elixir.Task.Supervised',invoke_mfa,2,[{file,"lib/task/supervised.ex"},{line,90}]},{'Elixir.Task.Supervised',reply,5,[{file,"lib/task/supervised.ex"},{line,35}]},{proc_lib,init_p_do_apply,3,[{file,"proc_lib.erl"},{line,249}]}]}
2019-11-19 00:00:00.028 [error] <0.1311.0>@Elixir.IO:chardata_to_string:557 CRASH REPORT Process <0.1311.0> with 0 neighbours crashed with reason: no function clause matching 'Elixir.IO':chardata_to_string(nil) line 557
2019-11-19 00:00:00.029 [error] <0.1158.0>@Elixir.IO:chardata_to_string:557 Supervisor 'Elixir.Archive.Scheduler.Task.Supervisor' had child undefined started with {'Elixir.Task.Supervised',start_link,undefined} at <0.1311.0> exit with reason no function clause matching 'Elixir.IO':chardata_to_string(nil) line 557 in context child_terminated
